<?xml version="1.0"?>
<robot name="jsc_mecanum_bot" xmlns:xacro="http://ros.org/wiki/xacro">
 
  <!--*************** MATERIALES ****************-->
  <material name="darkgrey">
    <color rgba="0.1 0.1 0.1 1.0" />
  </material>
  <material name="grey_blue">
    <color rgba="0.5 0.5 0.65 1.0" />
  </material>
  <material name="blue">
    <color rgba="0.0 0.0 0.8 1.0" />
  </material>
  <material name="black">
    <color rgba="0.0 0.0 0.0 1.0"/>
  </material>

  <!--*************** PROPIEDADES ****************-->
  <xacro:property name="M_PI" value="3.1415926535897931" />
  <xacro:property name="base_size_x" value="0.20" />
  <xacro:property name="base_size_y" value="0.075" />
  <xacro:property name="base_size_z" value="0.08" />
  <xacro:property name="base_mass" value="2.00" />

  <xacro:property name="wheel_radius" value="0.04" />
  <xacro:property name="wheel_width" value="0.035" />
  <xacro:property name="wheel_offset_x" value="0.063"/>
  <xacro:property name="wheel_offset_y" value="0.05"/>
  <xacro:property name="wheel_offset_z" value="0.01"/>
  <xacro:property name="wheel_mass" value="0.5"/>

  <!--*************** MACROS DE INERCIA ****************-->
  <xacro:macro name="box_inertia" params="m x y z">
    <inertia ixx="${m*(y*y+z*z)/12}" ixy="0" ixz="0"
             iyy="${m*(x*x+z*z)/12}" iyz="0"
             izz="${m*(x*x+y*y)/12}"/>
  </xacro:macro>
  <xacro:macro name="cylinder_inertia" params="m r w">
    <inertia ixx="${m*(3*r*r+w*w)/12}" ixy="0" ixz="0"
             iyy="${m*(3*r*r+w*w)/12}" iyz="0"
             izz="${m*r*r/2}"/>
  </xacro:macro>

  <!--*************** BASE FOOTPRINT ****************-->
  <link name="base_footprint" />

  <joint name="base_joint" type="fixed">
    <parent link="base_footprint" />
    <child link="base_link" />
    <origin xyz="0 0 0.02" rpy="0 0 0" />
  </joint>

  <link name="base_link">
    <visual>
      <origin xyz="0 0 0.04" rpy="0 0 0" />
      <geometry>
        <box size="${base_size_x} ${base_size_y} ${base_size_z}" />
      </geometry>
      <material name="grey_blue" />
    </visual>
    <collision>
      <origin xyz="0 0 0.04" rpy="0 0 0" />
      <geometry>
        <box size="${base_size_x} ${base_size_y} ${base_size_z}" />
      </geometry>
    </collision>
    <inertial>
      <origin xyz="0 0 0" rpy="0 0 0"/>
      <mass value="${base_mass}"/>
      <xacro:box_inertia m="${base_mass}" x="${base_size_x}" y="${base_size_y}" z="${base_size_z}"/>
    </inertial>
  </link>

  <!--*************** RUEDAS (4) ****************-->
  <xacro:macro name="wheel" params="name x y rpy_axis">
    <joint name="${name}_joint" type="continuous">
      <parent link="base_link"/>
      <child link="${name}_link"/>
      <origin xyz="${x} ${y} ${wheel_offset_z}" rpy="0 0 ${rpy_axis}"/>
      <axis xyz="1 0 0"/>
    </joint>
    <link name="${name}_link">
      <visual>
        <origin xyz="0 0 0" rpy="0 0 0"/>
        <geometry>
          <mesh filename="package://my_robot_description/meshes/${name}_link.STL" scale="0.6 0.6 0.6"/>
        </geometry>
        <material name="darkgrey"/>
      </visual>
      <collision>
        <origin xyz="0 0 0" rpy="0 0 0"/>
        <geometry>
          <cylinder radius="${wheel_radius}" length="${wheel_width}"/>
        </geometry>
      </collision>
      <inertial>
        <origin xyz="0 0 0" rpy="0 0 0"/>
        <mass value="${wheel_mass}"/>
        <xacro:cylinder_inertia m="${wheel_mass}" r="${wheel_radius}" w="${wheel_width}"/>
      </inertial>
    </link>
  </xacro:macro>

  <!-- Aplicamos las ruedas con la macro -->
  <xacro:wheel name="fl_wheel" x="${wheel_offset_x}" y="${wheel_offset_y}" rpy_axis="${M_PI/2}"/>
  <xacro:wheel name="fr_wheel" x="${wheel_offset_x}" y="${-wheel_offset_y}" rpy_axis="${-M_PI/2}"/>
  <xacro:wheel name="rl_wheel" x="${-wheel_offset_x}" y="${wheel_offset_y}" rpy_axis="${M_PI/2}"/>
  <xacro:wheel name="rr_wheel" x="${-wheel_offset_x}" y="${-wheel_offset_y}" rpy_axis="${-M_PI/2}"/>

</robot>
